<?xml version="1.0" ?>
<!-- =================================================================================== -->
<!-- |    This document was autogenerated by xacro from tx90xl.xacro                   | -->
<!-- |    EDITING THIS FILE BY HAND IS NOT RECOMMENDED                                 | -->
<!-- =================================================================================== -->
<robot name="staubli_tx90xl" xmlns:xacro="http://ros.org/wiki/xacro">
  <!-- colours based on RAL values supplied by Staubli -->
  <!-- all RAL colours converted using http://www.visual-graphics.de/en/customer-care/ral-colours -->
  <!-- default colours for robots -->
  <!-- RAL 1028 - Melon yellow - scara (non-textured) and 6-axis (textured) robots -->
  <!-- RAL 7035 - Light grey - scara robot ESD -->
  <!-- RAL 7045 - Telegrey 1 - scara robot base (textured) -->
  <!-- RAL 7047 - Telegrey 4 - paint (smooth) -->
  <!-- RAL 9007 - Grey aluminium - HE (smooth) -->
  <!-- RAL 9016 - Traffic white - CR (smooth) -->
  <!-- old colour definitions, for bw-compatibility. These are DEPRECATED. -->
  <!-- default colors for robots -->
  <!-- old material definitions, for bw-compatibility. These are DEPRECATED. -->
  <!-- links -->
  <link name="base_link">
    <visual>
      <origin rpy="0 0 0" xyz="0 0 0"/>
      <geometry>
        <mesh filename="package://staubli_tx90_support/meshes/tx90/visual/base_link.stl"/>
      </geometry>
      <material name="">
        <color rgba="1.0 0.607843137255 0.0 1.0"/>
      </material>
    </visual>
    <collision>
      <origin rpy="0 0 0" xyz="0 0 0"/>
      <geometry>
        <mesh filename="package://staubli_tx90_support/meshes/tx90/collision/base_link.stl"/>
      </geometry>
    </collision>
    <inertial>
      <mass value="10.733459"/>
      <origin rpy="0.0 0.0 0.0" xyz="0.014288 0.000001 0.122264"/>
      <inertia ixx="0.09659003750" ixy="-0.00000507582" ixz="-0.00380302939" iyy="0.08759138191" iyz="-0.00000102074" izz="0.08163249578"/>
    </inertial>
  </link>
  <link name="link_1">
    <visual>
      <origin rpy="0 0 0" xyz="0 0 0"/>
      <geometry>
        <mesh filename="package://staubli_tx90_support/meshes/tx90/visual/link_1.stl"/>
      </geometry>
      <material name="">
        <color rgba="1.0 0.607843137255 0.0 1.0"/>
      </material>
    </visual>
    <collision>
      <origin rpy="0 0 0" xyz="0 0 0"/>
      <geometry>
        <mesh filename="package://staubli_tx90_support/meshes/tx90/collision/link_1.stl"/>
      </geometry>
    </collision>
    <inertial>
      <mass value="16.934564"/>
      <origin rpy="0.0 0.0 0.0" xyz="0.019143 0.024764 -0.064596"/>
      <inertia ixx="0.222318" ixy="0.016499" ixz="0.023794" iyy="0.208959" iyz="0.031663" izz="0.157081"/>
    </inertial>
  </link>
  <link name="link_2">
    <visual>
      <origin rpy="0 0 0" xyz="0 0 0"/>
      <geometry>
        <mesh filename="package://staubli_tx90_support/meshes/tx90xl/visual/link_2.stl"/>
      </geometry>
      <material name="">
        <color rgba="1.0 0.607843137255 0.0 1.0"/>
      </material>
    </visual>
    <collision>
      <origin rpy="0 0 0" xyz="0 0 0"/>
      <geometry>
        <mesh filename="package://staubli_tx90_support/meshes/tx90xl/collision/link_2.stl"/>
      </geometry>
    </collision>
    <inertial>
      <mass value="17.789372"/>
      <origin rpy="0.0 0.0 0.0" xyz="-0.000005 0.219316 0.276936"/>
      <inertia ixx="1.071537" ixy="0.000005" ixz="-0.000015" iyy="1.108645" iyz="-0.007651" izz="0.074022"/>
    </inertial>
  </link>
  <link name="link_3">
    <visual>
      <origin rpy="0 0 0" xyz="0 0 0"/>
      <geometry>
        <mesh filename="package://staubli_tx90_support/meshes/tx90/visual/link_3.stl"/>
      </geometry>
      <material name="">
        <color rgba="1.0 0.607843137255 0.0 1.0"/>
      </material>
    </visual>
    <collision>
      <origin rpy="0 0 0" xyz="0 0 0"/>
      <geometry>
        <mesh filename="package://staubli_tx90_support/meshes/tx90/collision/link_3.stl"/>
      </geometry>
    </collision>
    <inertial>
      <mass value="7.501506"/>
      <origin rpy="0.0 0.0 0.0" xyz="0.000002 0.065008 0.003572"/>
      <inertia ixx="0.058902" ixy="0.000000" ixz="0.000001" iyy="0.056884" iyz="-0.003672" izz="0.034271"/>
    </inertial>
  </link>
  <link name="link_4">
    <visual>
      <origin rpy="0 0 0" xyz="0 0 0"/>
      <geometry>
        <mesh filename="package://staubli_tx90_support/meshes/tx90xl/visual/link_4.stl"/>
      </geometry>
      <material name="">
        <color rgba="1.0 0.607843137255 0.0 1.0"/>
      </material>
    </visual>
    <collision>
      <origin rpy="0 0 0" xyz="0 0 0"/>
      <geometry>
        <mesh filename="package://staubli_tx90_support/meshes/tx90xl/collision/link_4.stl"/>
      </geometry>
    </collision>
    <inertial>
      <mass value="7.916800"/>
      <origin rpy="0.0 0.0 0.0" xyz="-0.001746 0.050006 0.410582"/>
      <inertia ixx="0.188254" ixy="0.000042" ixz="-0.001998" iyy="0.182701" iyz="0.000005" izz="0.022684"/>
    </inertial>
  </link>
  <link name="link_5">
    <visual>
      <origin rpy="0 0 0" xyz="0 0 0"/>
      <geometry>
        <mesh filename="package://staubli_tx90_support/meshes/tx90/visual/link_5.stl"/>
      </geometry>
      <material name="">
        <color rgba="0.529411764706 0.521568627451 0.505882352941 1.0"/>
      </material>
    </visual>
    <collision>
      <origin rpy="0 0 0" xyz="0 0 0"/>
      <geometry>
        <mesh filename="package://staubli_tx90_support/meshes/tx90/collision/link_5.stl"/>
      </geometry>
    </collision>
    <inertial>
      <mass value="0.568760"/>
      <origin rpy="0.0 0.0 0.0" xyz="-0.000001 0.049931 0.022823"/>
      <inertia ixx="0.001084" ixy="0.000000" ixz="0.000000" iyy="0.001123" iyz="0.000001" izz="0.000383"/>
    </inertial>
  </link>
  <link name="link_6">
    <visual>
      <origin rpy="0 0 0" xyz="0 0 0"/>
      <geometry>
        <mesh filename="package://staubli_tx90_support/meshes/tx90/visual/link_6.stl"/>
      </geometry>
      <material name="">
        <color rgba="0.529411764706 0.521568627451 0.505882352941 1.0"/>
      </material>
    </visual>
    <collision>
      <origin rpy="0 0 0" xyz="0 0 0"/>
      <geometry>
        <mesh filename="package://staubli_tx90_support/meshes/tx90/collision/link_6.stl"/>
      </geometry>
    </collision>
    <inertial>
      <mass value="0.030977"/>
      <origin rpy="0.0 0.0 0.0" xyz="-0.000243 0.050001 -0.006293"/>
      <inertia ixx="0.000012" ixy="0.000000" ixz="0.000000" iyy="0.000011" iyz="0.000000" izz="0.000022"/>
    </inertial>
  </link>
  <link name="tool0"/>
  <!-- joints -->
  <joint name="joint_1" type="revolute">
    <origin rpy="0 0 0" xyz="0 0 0.478"/>
    <parent link="base_link"/>
    <child link="link_1"/>
    <axis xyz="0 0 1"/>
    <!-- from Staubli instruction manual:
      (1) effort limit = 318 Nm if floor mounted
      (2) effort limit = 111 Nm if wall mounted -->
    <limit effort="318.0" lower="-3.14159" upper="3.14159" velocity="3.32"/>
    <dynamics damping="0.0" friction="0.0"/>
  </joint>
  <joint name="joint_2" type="revolute">
    <origin rpy="0 0 0" xyz="0.050 0 0"/>
    <parent link="link_1"/>
    <child link="link_2"/>
    <axis xyz="0 1 0"/>
    <limit effort="90.0" lower="-2.268928" upper="2.574360" velocity="2.79"/>
    <dynamics damping="0.0" friction="0.0"/>
  </joint>
  <joint name="joint_3" type="revolute">
    <origin rpy="0 0 0" xyz="0 0.05 0.650"/>
    <parent link="link_2"/>
    <child link="link_3"/>
    <axis xyz="0 1 0"/>
    <limit effort="53.0" lower="-2.530727" upper="2.530727" velocity="4.01"/>
    <dynamics damping="0.0" friction="0.0"/>
  </joint>
  <joint name="joint_4" type="revolute">
    <origin rpy="0 0 0" xyz="0 0 0"/>
    <parent link="link_3"/>
    <child link="link_4"/>
    <axis xyz="0 0 1"/>
    <limit effort="34.0" lower="-4.712389" upper="4.712389" velocity="6.98"/>
    <dynamics damping="0.0" friction="0.0"/>
  </joint>
  <joint name="joint_5" type="revolute">
    <origin rpy="0 0 0" xyz="0 0 0.650"/>
    <parent link="link_4"/>
    <child link="link_5"/>
    <axis xyz="0 1 0"/>
    <limit effort="29.0" lower="-2.007129" upper="2.443461" velocity="6.02"/>
    <dynamics damping="0.0" friction="0.0"/>
  </joint>
  <joint name="joint_6" type="revolute">
    <origin rpy="0 0 0" xyz="0 0 0.100"/>
    <parent link="link_5"/>
    <child link="link_6"/>
    <axis xyz="0 0 1"/>
    <limit effort="11.0" lower="-4.712389" upper="4.712389" velocity="10.47"/>
    <dynamics damping="0.0" friction="0.0"/>
  </joint>
  <joint name="joint_6-tool0" type="fixed">
    <parent link="link_6"/>
    <child link="tool0"/>
    <origin rpy="0 0 0" xyz="0 0 0"/>
  </joint>
</robot>

